2018-07-18 15:48:57,636 INFO: Microblog startup [in /home/xochozomatli/Documents/mycode/python/microblog/app/__init__.py:44]
2018-07-18 16:12:31,445 INFO: Microblog startup [in /home/xochozomatli/Documents/mycode/python/microblog/app/__init__.py:44]
2018-07-18 16:15:12,141 INFO: Microblog startup [in /home/xochozomatli/Documents/mycode/python/microblog/app/__init__.py:44]
2018-07-18 16:15:50,209 INFO: Microblog startup [in /home/xochozomatli/Documents/mycode/python/microblog/app/__init__.py:44]
2018-07-18 17:37:55,047 INFO: Microblog startup [in /home/xochozomatli/Documents/mycode/python/microblog/app/__init__.py:44]
2018-07-18 18:57:19,792 INFO: Microblog startup [in /home/xochozomatli/Documents/mycode/python/microblog/app/__init__.py:44]
2018-07-18 19:05:59,684 INFO: Microblog startup [in /home/xochozomatli/Documents/mycode/python/microblog/app/__init__.py:44]
2018-07-18 19:06:34,794 ERROR: Exception on /user/ahmed [GET] [in /home/xochozomatli/Documents/mycode/python/microblog/venv/lib/python3.6/site-packages/flask/app.py:1761]
Traceback (most recent call last):
  File "/home/xochozomatli/Documents/mycode/python/microblog/venv/lib/python3.6/site-packages/flask/app.py", line 2292, in wsgi_app
    response = self.full_dispatch_request()
  File "/home/xochozomatli/Documents/mycode/python/microblog/venv/lib/python3.6/site-packages/flask/app.py", line 1815, in full_dispatch_request
    rv = self.handle_user_exception(e)
  File "/home/xochozomatli/Documents/mycode/python/microblog/venv/lib/python3.6/site-packages/flask/app.py", line 1718, in handle_user_exception
    reraise(exc_type, exc_value, tb)
  File "/home/xochozomatli/Documents/mycode/python/microblog/venv/lib/python3.6/site-packages/flask/_compat.py", line 35, in reraise
    raise value
  File "/home/xochozomatli/Documents/mycode/python/microblog/venv/lib/python3.6/site-packages/flask/app.py", line 1813, in full_dispatch_request
    rv = self.dispatch_request()
  File "/home/xochozomatli/Documents/mycode/python/microblog/venv/lib/python3.6/site-packages/flask/app.py", line 1799, in dispatch_request
    return self.view_functions[rule.endpoint](**req.view_args)
  File "/home/xochozomatli/Documents/mycode/python/microblog/venv/lib/python3.6/site-packages/flask_login/utils.py", line 261, in decorated_view
    return func(*args, **kwargs)
  File "/home/xochozomatli/Documents/mycode/python/microblog/app/routes.py", line 33, in user
    return render_template('user.html', user=user, posts=posts)
  File "/home/xochozomatli/Documents/mycode/python/microblog/venv/lib/python3.6/site-packages/flask/templating.py", line 135, in render_template
    context, ctx.app)
  File "/home/xochozomatli/Documents/mycode/python/microblog/venv/lib/python3.6/site-packages/flask/templating.py", line 117, in _render
    rv = template.render(context)
  File "/home/xochozomatli/Documents/mycode/python/microblog/venv/lib/python3.6/site-packages/jinja2/asyncsupport.py", line 76, in render
    return original_render(self, *args, **kwargs)
  File "/home/xochozomatli/Documents/mycode/python/microblog/venv/lib/python3.6/site-packages/jinja2/environment.py", line 1008, in render
    return self.environment.handle_exception(exc_info, True)
  File "/home/xochozomatli/Documents/mycode/python/microblog/venv/lib/python3.6/site-packages/jinja2/environment.py", line 780, in handle_exception
    reraise(exc_type, exc_value, tb)
  File "/home/xochozomatli/Documents/mycode/python/microblog/venv/lib/python3.6/site-packages/jinja2/_compat.py", line 37, in reraise
    raise value.with_traceback(tb)
  File "/home/xochozomatli/Documents/mycode/python/microblog/app/templates/user.html", line 1, in top-level template code
    {% extends "base.html" %}
  File "/home/xochozomatli/Documents/mycode/python/microblog/app/templates/base.html", line 30, in top-level template code
    {% block content %}
  File "/home/xochozomatli/Documents/mycode/python/microblog/app/templates/user.html", line 15, in block "content"
    <p><a href="{{ url_for('follow', username=user.username) }}">Follow</a></p>
  File "/home/xochozomatli/Documents/mycode/python/microblog/venv/lib/python3.6/site-packages/flask/helpers.py", line 356, in url_for
    return appctx.app.handle_url_build_error(error, endpoint, values)
  File "/home/xochozomatli/Documents/mycode/python/microblog/venv/lib/python3.6/site-packages/flask/app.py", line 2061, in handle_url_build_error
    reraise(exc_type, exc_value, tb)
  File "/home/xochozomatli/Documents/mycode/python/microblog/venv/lib/python3.6/site-packages/flask/_compat.py", line 35, in reraise
    raise value
  File "/home/xochozomatli/Documents/mycode/python/microblog/venv/lib/python3.6/site-packages/flask/helpers.py", line 345, in url_for
    force_external=external)
  File "/home/xochozomatli/Documents/mycode/python/microblog/venv/lib/python3.6/site-packages/werkzeug/routing.py", line 1776, in build
    raise BuildError(endpoint, values, method, self)
werkzeug.routing.BuildError: Could not build url for endpoint 'follow' with values ['username']. Did you mean 'login' instead?
2018-07-18 19:13:21,602 INFO: Microblog startup [in /home/xochozomatli/Documents/mycode/python/microblog/app/__init__.py:44]
2018-07-19 01:36:10,729 INFO: Microblog startup [in /home/xochozomatli/Documents/mycode/python/microblog/app/__init__.py:44]
2018-07-19 01:36:47,149 INFO: Microblog startup [in /home/xochozomatli/Documents/mycode/python/microblog/app/__init__.py:44]
2018-07-19 01:37:50,015 INFO: Microblog startup [in /home/xochozomatli/Documents/mycode/python/microblog/app/__init__.py:44]
2018-07-19 01:41:12,570 INFO: Microblog startup [in /home/xochozomatli/Documents/mycode/python/microblog/app/__init__.py:44]
